Workbook

Sheet Riepilogo
A1: Prospetto Margine Economico - CENSINI PAOLO
A2: Fonte: export HTML 'Quadro Economico' fornito dall'utente. Valori del periodo di competenza.
A4: Voce | B4: Valore (€) | C4: % su ricavi
A5: Ricavi | B5: =Commesse!G86 -> 1723909.9 | C5: =IF($B$5=0,"",B5/$B$5) -> 1
A6: Costi diretti | B6: =Commesse!I86 -> 1341251.5 | C6: =IF($B$5=0,"",B6/$B$5) -> 0.77802876
A7: MLC (margine lordo di commessa) | B7: =Commesse!K86 -> 382658.42 | C7: =IF($B$5=0,"",B7/$B$5) -> 0.22197124
A8: Fatturato | B8: =Commesse!N86 -> 1756792.8 | C8: =IF($B$5=0,"",B8/$B$5) -> 1.0190746
A9: Scostamento ricavi competenza - fatturato | B9: =Commesse!O86 -> -32882.9 | C9: =IF($B$5=0,"",B9/$B$5) -> -0.019074605
A11: Per sezione | B11: Ricavi (€) | C11: Costi (€) | D11: MLC (€) | E11: % MLC | F11: Fatturato (€) | G11: N. commesse
A12: Standard | B12: =SUMIFS(Commesse!$G$5:$G$85,Commesse!$A$5:$A$85,A12) -> 1591488.5 | C12: =SUMIFS(Commesse!$I$5:$I$85,Commesse!$A$5:$A$85,A12) -> 1301375 | D12: =B12-C12 -> 290113.48 | E12: =IF(B12=0,"",D12/B12) -> 0.18229066 | F12: =SUMIFS(Commesse!$N$5:$N$85,Commesse!$A$5:$A$85,A12) -> 1591488.5 | G12: =COUNTIF(Commesse!$A$5:$A$85,A12) -> 32
A13: Economie | B13: =SUMIFS(Commesse!$G$5:$G$85,Commesse!$A$5:$A$85,A13) -> 132421.44 | C13: =SUMIFS(Commesse!$I$5:$I$85,Commesse!$A$5:$A$85,A13) -> 39876.5 | D13: =B13-C13 -> 92544.94 | E13: =IF(B13=0,"",D13/B13) -> 0.69886674 | F13: =SUMIFS(Commesse!$N$5:$N$85,Commesse!$A$5:$A$85,A13) -> 165304.34 | G13: =COUNTIF(Commesse!$A$5:$A$85,A13) -> 49
A15: Indicatori
A16: Numero commesse | B16: =COUNTA(Commesse!B5:B85) -> 81
A17: Commesse con MLC negativo | B17: =COUNTIF(Commesse!K5:K85,"<0") -> 6
A18: MLC perso sulle commesse in perdita (€) | B18: =SUMIF(Commesse!K5:K85,"<0") -> -155115.83
A19: Numero righe (base + quadri + varianti + economie) | B19: =COUNTA(Dettaglio!C5:C126) -> 122
A20: Controllo: totale Dettaglio = totale Commesse | B20: =IF(AND(ROUND(Dettaglio!I127-Commesse!G86,2)=0,ROUND(Dettaglio!J127-Commesse!I86,2)=0,ROUND(Dettaglio!M127-Commesse!N86,2)=0),"OK","ERRORE") -> OK
A22: Legenda
A23: Testo blu = valore copiato dal report (dato di input)
A24: Testo nero = formula
A25: Sfondo rosso = valore negativo (MLC o scostamento)

Sheet Commesse
A1: Prospetto Margine Economico - CENSINI PAOLO
A2: Valori del periodo di competenza. Ricavi, costi e fatturato = somma delle righe del foglio Dettaglio.
A4: Sezione | B4: Commessa | C4: Descrizione | D4: Cod. cliente | E4: Cliente | F4: Stato | G4: Ricavi (€) | H4: % Inc. ricavi | I4: Costi diretti (€) | J4: % Inc. costi | K4: MLC (€) | L4: % Inc. MLC | M4: % MLC | N4: Fatturato (€) | O4: Scostamento ricavi - fatturato (€) | P4: N. varianti | Q4: Avvisi
A5: Standard | B5: S1185 | C5: MONTE ARGENTARIO GESTIONE ILLUMINAZIONE PUBBLICA COMUNALE | D5: 00294 | E5: EDISON NEXT GOVERNMENT S.R.L. | F5: In Progress | G5: =SUMIFS(Dettaglio!$I$5:$I$126,Dettaglio!$B$5:$B$126,B5) -> 56408.45 | H5: =IF($G$86=0,"",G5/$G$86) -> 0.032721229 | I5: =SUMIFS(Dettaglio!$J$5:$J$126,Dettaglio!$B$5:$B$126,B5) -> 16415.78 | J5: =IF($I$86=0,"",I5/$I$86) -> 0.012239151 | K5: =G5-I5 -> 39992.67 | L5: =IF($K$86=0,"",K5/$K$86) -> 0.10451271 | M5: =IF(G5=0,"",K5/G5) -> 0.70898367 | N5: =SUMIFS(Dettaglio!$M$5:$M$126,Dettaglio!$B$5:$B$126,B5) -> 56408.45 | O5: =G5-N5 -> 0 | P5: =COUNTIFS(Dettaglio!$B$5:$B$126,B5,Dettaglio!$D$5:$D$126,"Quadro")+COUNTIFS(Dettaglio!$B$5:$B$126,B5,Dettaglio!$D$5:$D$126,"Variante") -> 2 | Q5: Costi previsti a zero
A6: Standard | B6: S1186 | C6: ORBETELLO GESTIONE ILLUMINAZIONE PUBBLICA COMUNALE | D6: 00294 | E6: EDISON NEXT GOVERNMENT S.R.L. | F6: In Progress | G6: =SUMIFS(Dettaglio!$I$5:$I$126,Dettaglio!$B$5:$B$126,B6) -> 78988.49 | H6: =IF($G$86=0,"",G6/$G$86) -> 0.045819384 | I6: =SUMIFS(Dettaglio!$J$5:$J$126,Dettaglio!$B$5:$B$126,B6) -> 43665.83 | J6: =IF($I$86=0,"",I6/$I$86) -> 0.032556035 | K6: =G6-I6 -> 35322.66 | L6: =IF($K$86=0,"",K6/$K$86) -> 0.092308592 | M6: =IF(G6=0,"",K6/G6) -> 0.44718743 | N6: =SUMIFS(Dettaglio!$M$5:$M$126,Dettaglio!$B$5:$B$126,B6) -> 78988.49 | O6: =G6-N6 -> 0 | P6: =COUNTIFS(Dettaglio!$B$5:$B$126,B6,Dettaglio!$D$5:$D$126,"Quadro")+COUNTIFS(Dettaglio!$B$5:$B$126,B6,Dettaglio!$D$5:$D$126,"Variante") -> 4 | Q6: Costi previsti a zero
A7: Standard | B7: S1386 | C7: FORNITURA IN OPERA DI APPARATI PER L'IMPLEMENTAZIONE E MANUTANZIONE EVOLUTIVA DEI SISTEMI DI TELECONTROLLO PROSSO I SITI ACEA | D7: 00311 | E7: ACEA INFRASTRUCTURE S.p.A. - GRUPPO ACEA | F7: In Progress | G7: =SUMIFS(Dettaglio!$I$5:$I$126,Dettaglio!$B$5:$B$126,B7) -> 0 | H7: =IF($G$86=0,"",G7/$G$86) -> 0 | I7: =SUMIFS(Dettaglio!$J$5:$J$126,Dettaglio!$B$5:$B$126,B7) -> 1225.38 | J7: =IF($I$86=0,"",I7/$I$86) -> 0.00091360943 | K7: =G7-I7 -> -1225.38 | L7: =IF($K$86=0,"",K7/$K$86) -> -0.0032022816 | M7: =IF(G7=0,"",K7/G7) | N7: =SUMIFS(Dettaglio!$M$5:$M$126,Dettaglio!$B$5:$B$126,B7) -> 0 | O7: =G7-N7 -> 0 | P7: =COUNTIFS(Dettaglio!$B$5:$B$126,B7,Dettaglio!$D$5:$D$126,"Quadro")+COUNTIFS(Dettaglio!$B$5:$B$126,B7,Dettaglio!$D$5:$D$126,"Variante") -> 1 | Q7: Costi previsti a zero
A8: Standard | B8: S1419 | C8: SOSTITUZIONE DEI PUNTI LUCE A SERVIZIO DELL'IMPIANTO DI ILLUMINAZIONE DEL CAMPO SPORTIVO DI ALBINIA | D8: 00017 | E8: COMUNE DI ORBETELLO | F8: Chiusa | G8: =SUMIFS(Dettaglio!$I$5:$I$126,Dettaglio!$B$5:$B$126,B8) -> 0 | H8: =IF($G$86=0,"",G8/$G$86) -> 0 | I8: =SUMIFS(Dettaglio!$J$5:$J$126,Dettaglio!$B$5:$B$126,B8) -> 1367.26 | J8: =IF($I$86=0,"",I8/$I$86) -> 0.0010193912 | K8: =G8-I8 -> -1367.26 | L8: =IF($K$86=0,"",K8/$K$86) -> -0.0035730561 | M8: =IF(G8=0,"",K8/G8) | N8: =SUMIFS(Dettaglio!$M$5:$M$126,Dettaglio!$B$5:$B$126,B8) -> 0 | O8: =G8-N8 -> 0 | P8: =COUNTIFS(Dettaglio!$B$5:$B$126,B8,Dettaglio!$D$5:$D$126,"Quadro")+COUNTIFS(Dettaglio!$B$5:$B$126,B8,Dettaglio!$D$5:$D$126,"Variante") -> 0 | Q8: Costi previsti a zero
A9: Standard | B9: S1483 | C9: Fornitura in opera di apparati per l'implementazione e manutenzione evolutiva dei sistemi di Telecontrollo 2023 2024 | D9: 00311 | E9: ACEA INFRASTRUCTURE S.p.A. - GRUPPO ACEA | F9: Chiusa | G9: =SUMIFS(Dettaglio!$I$5:$I$126,Dettaglio!$B$5:$B$126,B9) -> 153917.88 | H9: =IF($G$86=0,"",G9/$G$86) -> 0.089284179 | I9: =SUMIFS(Dettaglio!$J$5:$J$126,Dettaglio!$B$5:$B$126,B9) -> 70517.53 | J9: =IF($I$86=0,"",I9/$I$86) -> 0.05257592 | K9: =G9-I9 -> 83400.35 | L9: =IF($K$86=0,"",K9/$K$86) -> 0.21794986 | M9: =IF(G9=0,"",K9/G9) -> 0.54184965 | N9: =SUMIFS(Dettaglio!$M$5:$M$126,Dettaglio!$B$5:$B$126,B9) -> 153917.88 | O9: =G9-N9 -> 0 | P9: =COUNTIFS(Dettaglio!$B$5:$B$126,B9,Dettaglio!$D$5:$D$126,"Quadro")+COUNTIFS(Dettaglio!$B$5:$B$126,B9,Dettaglio!$D$5:$D$126,"Variante") -> 12 | Q9: Costi previsti a zero
A10: Standard | B10: S1818 | C10: INSTALLAZIONE GATEWAY E ANTENNE LORA - PISA E CASCINA | D10: 00335 | E10: ACQUE SPA | F10: Chiusa | G10: =SUMIFS(Dettaglio!$I$5:$I$126,Dettaglio!$B$5:$B$126,B10) -> 4909.32 | H10: =IF($G$86=0,"",G10/$G$86) -> 0.0028477822 | I10: =SUMIFS(Dettaglio!$J$5:$J$126,Dettaglio!$B$5:$B$126,B10) -> 0 | J10: =IF($I$86=0,"",I10/$I$86) -> 0 | K10: =G10-I10 -> 4909.32 | L10: =IF($K$86=0,"",K10/$K$86) -> 0.01282951 | M10: =IF(G10=0,"",K10/G10) -> 1 | N10: =SUMIFS(Dettaglio!$M$5:$M$126,Dettaglio!$B$5:$B$126,B10) -> 4909.32 | O10: =G10-N10 -> 0 | P10: =COUNTIFS(Dettaglio!$B$5:$B$126,B10,Dettaglio!$D$5:$D$126,"Quadro")+COUNTIFS(Dettaglio!$B$5:$B$126,B10,Dettaglio!$D$5:$D$126,"Variante") -> 1 | Q10: Costi previsti a zero
A11: Standard | B11: S1836 | C11: Conduzione e controllo potabilizzatore Giannutri periodo 2024/2027 | D11: 00050 | E11: ACQUEDOTTO DEL FIORA S.P.A. | F11: Nuova | G11: =SUMIFS(Dettaglio!$I$5:$I$126,Dettaglio!$B$5:$B$126,B11) -> 20794.48 | H11: =IF($G$86=0,"",G11/$G$86) -> 0.012062394 | I11: =SUMIFS(Dettaglio!$J$5:$J$126,Dettaglio!$B$5:$B$126,B11) -> 67.82 | J11: =IF($I$86=0,"",I11/$I$86) -> 5.0564716e-05 | K11: =G11-I11 -> 20726.66 | L11: =IF($K$86=0,"",K11/$K$86) -> 0.054164913 | M11: =IF(G11=0,"",K11/G11) -> 0.99673856 | N11: =SUMIFS(Dettaglio!$M$5:$M$126,Dettaglio!$B$5:$B$126,B11) -> 20794.48 | O11: =G11-N11 -> 0 | P11: =COUNTIFS(Dettaglio!$B$5:$B$126,B11,Dettaglio!$D$5:$D$126,"Quadro")+COUNTIFS(Dettaglio!$B$5:$B$126,B11,Dettaglio!$D$5:$D$126,"Variante") -> 0 | Q11: Costi previsti a zero
A12: Standard | B12: S1860 | C12: Fornitura in opera di apparati per l'implementazione e manutenzione evolutiva dei sistemi di Telecontrollo 2025 2026 | D12: 00311 | E12: ACEA INFRASTRUCTURE S.p.A. - GRUPPO ACEA | F12: In Progress | G12: =SUMIFS(Dettaglio!$I$5:$I$126,Dettaglio!$B$5:$B$126,B12) -> 202199.67 | H12: =IF($G$86=0,"",G12/$G$86) -> 0.11729132 | I12: =SUMIFS(Dettaglio!$J$5:$J$126,Dettaglio!$B$5:$B$126,B12) -> 319565.61 | J12: =IF($I$86=0,"",I12/$I$86) -> 0.23825928 | K12: =G12-I12 -> -117365.94 | L12: =IF($K$86=0,"",K12/$K$86) -> -0.30671203 | M12: =IF(G12=0,"",K12/G12) -> -0.58044575 | N12: =SUMIFS(Dettaglio!$M$5:$M$126,Dettaglio!$B$5:$B$126,B12) -> 202199.67 | O12: =G12-N12 -> 0 | P12: =COUNTIFS(Dettaglio!$B$5:$B$126,B12,Dettaglio!$D$5:$D$126,"Quadro")+COUNTIFS(Dettaglio!$B$5:$B$126,B12,Dettaglio!$D$5:$D$126,"Variante") -> 10 | Q12: Costi previsti a zero
A13: Standard | B13: S1861 | C13: QUADRO ELETTRICO SGRIGLIATORI ANSEDONIA | D13: 00248 | E13: REGIONE TOSCANA - GIUNTA REGIONALE | F13: Chiusa | G13: =SUMIFS(Dettaglio!$I$5:$I$126,Dettaglio!$B$5:$B$126,B13) -> 50900 | H13: =IF($G$86=0,"",G13/$G$86) -> 0.029525905 | I13: =SUMIFS(Dettaglio!$J$5:$J$126,Dettaglio!$B$5:$B$126,B13) -> 23663.66 | J13: =IF($I$86=0,"",I13/$I$86) -> 0.01764297 | K13: =G13-I13 -> 27236.34 | L13: =IF($K$86=0,"",K13/$K$86) -> 0.071176638 | M13: =IF(G13=0,"",K13/G13) -> 0.53509509 | N13: =SUMIFS(Dettaglio!$M$5:$M$126,Dettaglio!$B$5:$B$126,B13) -> 50900 | O13: =G13-N13 -> 0 | P13: =COUNTIFS(Dettaglio!$B$5:$B$126,B13,Dettaglio!$D$5:$D$126,"Quadro")+COUNTIFS(Dettaglio!$B$5:$B$126,B13,Dettaglio!$D$5:$D$126,"Variante") -> 1 | Q13: Costi previsti a zero
A14: Standard | B14: S1873 | C14: LINEE ENERGIA ELETTRICA - ACQUA POTABILE E TVCC EX AERONAUTICA | D14: 00002 | E14: COMUNE DI MONTE ARGENTARIO | F14: Chiusa | G14: =SUMIFS(Dettaglio!$I$5:$I$126,Dettaglio!$B$5:$B$126,B14) -> 56374.08 | H14: =IF($G$86=0,"",G14/$G$86) -> 0.032701291 | I14: =SUMIFS(Dettaglio!$J$5:$J$126,Dettaglio!$B$5:$B$126,B14) -> 36141.11 | J14: =IF($I$86=0,"",I14/$I$86) -> 0.026945812 | K14: =G14-I14 -> 20232.97 | L14: =IF($K$86=0,"",K14/$K$86) -> 0.052874754 | M14: =IF(G14=0,"",K14/G14) -> 0.35890555 | N14: =SUMIFS(Dettaglio!$M$5:$M$126,Dettaglio!$B$5:$B$126,B14) -> 56374.08 | O14: =G14-N14 -> 0 | P14: =COUNTIFS(Dettaglio!$B$5:$B$126,B14,Dettaglio!$D$5:$D$126,"Quadro")+COUNTIFS(Dettaglio!$B$5:$B$126,B14,Dettaglio!$D$5:$D$126,"Variante") -> 0
A15: Standard | B15: S1875 | C15: EFFICIENTAMENTO ENERGETICO ILLUMINAZIONE ESTERNA DI VILLA ILVANA | D15: 00348 | E15: COMUNE DI MONTALTO DI CASTRO | F15: Chiusa | G15: =SUMIFS(Dettaglio!$I$5:$I$126,Dettaglio!$B$5:$B$126,B15) -> 57217 | H15: =IF($G$86=0,"",G15/$G$86) -> 0.03319025 | I15: =SUMIFS(Dettaglio!$J$5:$J$126,Dettaglio!$B$5:$B$126,B15) -> 20578.35 | J15: =IF($I$86=0,"",I15/$I$86) -> 0.015342648 | K15: =G15-I15 -> 36638.65 | L15: =IF($K$86=0,"",K15/$K$86) -> 0.095747664 | M15: =IF(G15=0,"",K15/G15) -> 0.64034553 | N15: =SUMIFS(Dettaglio!$M$5:$M$126,Dettaglio!$B$5:$B$126,B15) -> 57217 | O15: =G15-N15 -> 0 | P15: =COUNTIFS(Dettaglio!$B$5:$B$126,B15,Dettaglio!$D$5:$D$126,"Quadro")+COUNTIFS(Dettaglio!$B$5:$B$126,B15,Dettaglio!$D$5:$D$126,"Variante") -> 0
A16: Standard | B16: S1892 | C16: TARGHE USCITE EMERGENZA CORSI MASCHERATI 2025 | D16: 00446 | E16: ASSOCIAZIONE CARNEVALETTO DA TRE SOLDI | F16: Chiusa | G16: =SUMIFS(Dettaglio!$I$5:$I$126,Dettaglio!$B$5:$B$126,B16) -> 1396.2 | H16: =IF($G$86=0,"",G16/$G$86) -> 0.00080990312 | I16: =SUMIFS(Dettaglio!$J$5:$J$126,Dettaglio!$B$5:$B$126,B16) -> 623.83 | J16: =IF($I$86=0,"",I16/$I$86) -> 0.00046511039 | K16: =G16-I16 -> 772.37 | L16: =IF($K$86=0,"",K16/$K$86) -> 0.002018432 | M16: =IF(G16=0,"",K16/G16) -> 0.55319438 | N16: =SUMIFS(Dettaglio!$M$5:$M$126,Dettaglio!$B$5:$B$126,B16) -> 1396.2 | O16: =G16-N16 -> 0 | P16: =COUNTIFS(Dettaglio!$B$5:$B$126,B16,Dettaglio!$D$5:$D$126,"Quadro")+COUNTIFS(Dettaglio!$B$5:$B$126,B16,Dettaglio!$D$5:$D$126,"Variante") -> 0 | Q16: Costi previsti a zero
A17: Standard | B17: S1894 | C17: RIFACIMENTO QUADRO ELETTRICO PARCHEGGIO LA CAVA PORTO SANTO STEFANO | D17: 00002 | E17: COMUNE DI MONTE ARGENTARIO | F17: Chiusa | G17: =SUMIFS(Dettaglio!$I$5:$I$126,Dettaglio!$B$5:$B$126,B17) -> 3850 | H17: =IF($G$86=0,"",G17/$G$86) -> 0.0022332954 | I17: =SUMIFS(Dettaglio!$J$5:$J$126,Dettaglio!$B$5:$B$126,B17) -> 2247.1 | J17: =IF($I$86=0,"",I17/$I$86) -> 0.0016753756 | K17: =G17-I17 -> 1602.9 | L17: =IF($K$86=0,"",K17/$K$86) -> 0.0041888533 | M17: =IF(G17=0,"",K17/G17) -> 0.41633766 | N17: =SUMIFS(Dettaglio!$M$5:$M$126,Dettaglio!$B$5:$B$126,B17) -> 3850 | O17: =G17-N17 -> 0 | P17: =COUNTIFS(Dettaglio!$B$5:$B$126,B17,Dettaglio!$D$5:$D$126,"Quadro")+COUNTIFS(Dettaglio!$B$5:$B$126,B17,Dettaglio!$D$5:$D$126,"Variante") -> 0
A18: Standard | B18: S1913 | C18: COMUNE ORBETELLO INSTALLAZIONE SISTEMI TOFOLAMP | D18: 00017 | E18: COMUNE DI ORBETELLO | F18: In Progress | G18: =SUMIFS(Dettaglio!$I$5:$I$126,Dettaglio!$B$5:$B$126,B18) -> 49510.25 | H18: =IF($G$86=0,"",G18/$G$86) -> 0.028719743 | I18: =SUMIFS(Dettaglio!$J$5:$J$126,Dettaglio!$B$5:$B$126,B18) -> 22161.3 | J18: =IF($I$86=0,"",I18/$I$86) -> 0.016522852 | K18: =G18-I18 -> 27348.95 | L18: =IF($K$86=0,"",K18/$K$86) -> 0.071470922 | M18: =IF(G18=0,"",K18/G18) -> 0.55238966 | N18: =SUMIFS(Dettaglio!$M$5:$M$126,Dettaglio!$B$5:$B$126,B18) -> 49510.25 | O18: =G18-N18 -> 0 | P18: =COUNTIFS(Dettaglio!$B$5:$B$126,B18,Dettaglio!$D$5:$D$126,"Quadro")+COUNTIFS(Dettaglio!$B$5:$B$126,B18,Dettaglio!$D$5:$D$126,"Variante") -> 0 | Q18: Costi previsti a zero
A19: Standard | B19: S1917 | C19: IMPIANTO ELETTRICO ALIMENTAZIONE GRUPPI PRESE PIAZZA PER FORNITURE TEMPORANEE SPETTACOLI ED EVENTI | D19: 00002 | E19: COMUNE DI MONTE ARGENTARIO | F19: Chiusa | G19: =SUMIFS(Dettaglio!$I$5:$I$126,Dettaglio!$B$5:$B$126,B19) -> 23983.97 | H19: =IF($G$86=0,"",G19/$G$86) -> 0.013912543 | I19: =SUMIFS(Dettaglio!$J$5:$J$126,Dettaglio!$B$5:$B$126,B19) -> 11646.83 | J19: =IF($I$86=0,"",I19/$I$86) -> 0.0086835543 | K19: =G19-I19 -> 12337.14 | L19: =IF($K$86=0,"",K19/$K$86) -> 0.032240608 | M19: =IF(G19=0,"",K19/G19) -> 0.51439107 | N19: =SUMIFS(Dettaglio!$M$5:$M$126,Dettaglio!$B$5:$B$126,B19) -> 23983.97 | O19: =G19-N19 -> 0 | P19: =COUNTIFS(Dettaglio!$B$5:$B$126,B19,Dettaglio!$D$5:$D$126,"Quadro")+COUNTIFS(Dettaglio!$B$5:$B$126,B19,Dettaglio!$D$5:$D$126,"Variante") -> 2 | Q19: Costi previsti a zero
A20: Standard | B20: S1931 | C20: CAMPAGNA DEL POMODORO 2025 | D20: 00119 | E20: CONSERVE ITALIA SOC. COOP. AGRICOLA | F20: Chiusa | G20: =SUMIFS(Dettaglio!$I$5:$I$126,Dettaglio!$B$5:$B$126,B20) -> 8820 | H20: =IF($G$86=0,"",G20/$G$86) -> 0.0051162767 | I20: =SUMIFS(Dettaglio!$J$5:$J$126,Dettaglio!$B$5:$B$126,B20) -> 3834 | J20: =IF($I$86=0,"",I20/$I$86) -> 0.0028585243 | K20: =G20-I20 -> 4986 | L20: =IF($K$86=0,"",K20/$K$86) -> 0.013029898 | M20: =IF(G20=0,"",K20/G20) -> 0.56530612 | N20: =SUMIFS(Dettaglio!$M$5:$M$126,Dettaglio!$B$5:$B$126,B20) -> 8820 | O20: =G20-N20 -> 0 | P20: =COUNTIFS(Dettaglio!$B$5:$B$126,B20,Dettaglio!$D$5:$D$126,"Quadro")+COUNTIFS(Dettaglio!$B$5:$B$126,B20,Dettaglio!$D$5:$D$126,"Variante") -> 0 | Q20: Costi previsti a zero
A21: Standard | B21: S1936 | C21: INSTALLAZIONE QUADRO GENERALE CONTATORI NUOVA SCUOLA ELEMENTARE DI ALBINIA | D21: 00017 | E21: COMUNE DI ORBETELLO | F21: Chiusa | G21: =SUMIFS(Dettaglio!$I$5:$I$126,Dettaglio!$B$5:$B$126,B21) -> 4959 | H21: =IF($G$86=0,"",G21/$G$86) -> 0.0028766005 | I21: =SUMIFS(Dettaglio!$J$5:$J$126,Dettaglio!$B$5:$B$126,B21) -> 3096.11 | J21: =IF($I$86=0,"",I21/$I$86) -> 0.002308374 | K21: =G21-I21 -> 1862.89 | L21: =IF($K$86=0,"",K21/$K$86) -> 0.0048682844 | M21: =IF(G21=0,"",K21/G21) -> 0.3756584 | N21: =SUMIFS(Dettaglio!$M$5:$M$126,Dettaglio!$B$5:$B$126,B21) -> 4959 | O21: =G21-N21 -> 0 | P21: =COUNTIFS(Dettaglio!$B$5:$B$126,B21,Dettaglio!$D$5:$D$126,"Quadro")+COUNTIFS(Dettaglio!$B$5:$B$126,B21,Dettaglio!$D$5:$D$126,"Variante") -> 0 | Q21: Costi previsti a zero
A22: Standard | B22: S1937 | C22: INTERVENTO DI RINNOVO E POTENZIAMENTO IMPIANTO DI DISSALAZIONE IN LOC. BONSERE, COMUNE DI ISOLA DEL GIGLIO CUP I61D22000120006 | D22: 00050 | E22: ACQUEDOTTO DEL FIORA S.P.A. | F22: In Progress | G22: =SUMIFS(Dettaglio!$I$5:$I$126,Dettaglio!$B$5:$B$126,B22) -> 568923.01 | H22: =IF($G$86=0,"",G22/$G$86) -> 0.33001899 | I22: =SUMIFS(Dettaglio!$J$5:$J$126,Dettaglio!$B$5:$B$126,B22) -> 573021.28 | J22: =IF($I$86=0,"",I22/$I$86) -> 0.42722881 | K22: =G22-I22 -> -4098.27 | L22: =IF($K$86=0,"",K22/$K$86) -> -0.010709996 | M22: =IF(G22=0,"",K22/G22) -> -0.0072035582 | N22: =SUMIFS(Dettaglio!$M$5:$M$126,Dettaglio!$B$5:$B$126,B22) -> 568923.01 | O22: =G22-N22 -> 0 | P22: =COUNTIFS(Dettaglio!$B$5:$B$126,B22,Dettaglio!$D$5:$D$126,"Quadro")+COUNTIFS(Dettaglio!$B$5:$B$126,B22,Dettaglio!$D$5:$D$126,"Variante") -> 7 | Q22: Costi previsti a zero
A23: Standard | B23: S1957 | C23: LAVORI DI RIPRISTINO ALLACCIO PUNTI LUCE STRADALI NUOVA ROTATORIA PORTO ERCOLE | D23: 00002 | E23: COMUNE DI MONTE ARGENTARIO | F23: Chiusa | G23: =SUMIFS(Dettaglio!$I$5:$I$126,Dettaglio!$B$5:$B$126,B23) -> 1746.77 | H23: =IF($G$86=0,"",G23/$G$86) -> 0.0010132606 | I23: =SUMIFS(Dettaglio!$J$5:$J$126,Dettaglio!$B$5:$B$126,B23) -> 579.22 | J23: =IF($I$86=0,"",I23/$I$86) -> 0.00043185041 | K23: =G23-I23 -> 1167.55 | L23: =IF($K$86=0,"",K23/$K$86) -> 0.0030511546 | M23: =IF(G23=0,"",K23/G23) -> 0.66840511 | N23: =SUMIFS(Dettaglio!$M$5:$M$126,Dettaglio!$B$5:$B$126,B23) -> 1746.77 | O23: =G23-N23 -> 0 | P23: =COUNTIFS(Dettaglio!$B$5:$B$126,B23,Dettaglio!$D$5:$D$126,"Quadro")+COUNTIFS(Dettaglio!$B$5:$B$126,B23,Dettaglio!$D$5:$D$126,"Variante") -> 0 | Q23: Costi previsti a zero
A24: Standard | B24: S1958 | C24: ALLACCIO ELETTRICO PUNTI LUCE NUOVA ROTATORIA PORTO ERCOLE | D24: 00735 | E24: FRATELLI MASSAI s.r.l. | F24: Chiusa | G24: =SUMIFS(Dettaglio!$I$5:$I$126,Dettaglio!$B$5:$B$126,B24) -> 2500 | H24: =IF($G$86=0,"",G24/$G$86) -> 0.0014501918 | I24: =SUMIFS(Dettaglio!$J$5:$J$126,Dettaglio!$B$5:$B$126,B24) -> 1573.35 | J24: =IF($I$86=0,"",I24/$I$86) -> 0.0011730462 | K24: =G24-I24 -> 926.65 | L24: =IF($K$86=0,"",K24/$K$86) -> 0.0024216114 | M24: =IF(G24=0,"",K24/G24) -> 0.37066 | N24: =SUMIFS(Dettaglio!$M$5:$M$126,Dettaglio!$B$5:$B$126,B24) -> 2500 | O24: =G24-N24 -> 0 | P24: =COUNTIFS(Dettaglio!$B$5:$B$126,B24,Dettaglio!$D$5:$D$126,"Quadro")+COUNTIFS(Dettaglio!$B$5:$B$126,B24,Dettaglio!$D$5:$D$126,"Variante") -> 0
A25: Standard | B25: S1961 | C25: Fornitura di n. 3 Elettromiscelatori comprensivi di adattatore per le stazioni di pompaggio di Ansedonia e di Nassa | D25: 00248 | E25: REGIONE TOSCANA - GIUNTA REGIONALE | F25: Chiusa | G25: =SUMIFS(Dettaglio!$I$5:$I$126,Dettaglio!$B$5:$B$126,B25) -> 103620 | H25: =IF($G$86=0,"",G25/$G$86) -> 0.06010755 | I25: =SUMIFS(Dettaglio!$J$5:$J$126,Dettaglio!$B$5:$B$126,B25) -> 60838.48 | J25: =IF($I$86=0,"",I25/$I$86) -> 0.045359488 | K25: =G25-I25 -> 42781.52 | L25: =IF($K$86=0,"",K25/$K$86) -> 0.11180081 | M25: =IF(G25=0,"",K25/G25) -> 0.41286933 | N25: =SUMIFS(Dettaglio!$M$5:$M$126,Dettaglio!$B$5:$B$126,B25) -> 103620 | O25: =G25-N25 -> 0 | P25: =COUNTIFS(Dettaglio!$B$5:$B$126,B25,Dettaglio!$D$5:$D$126,"Quadro")+COUNTIFS(Dettaglio!$B$5:$B$126,B25,Dettaglio!$D$5:$D$126,"Variante") -> 0 | Q25: Costi previsti a zero
A26: Standard | B26: S1963 | C26: REALIZZAZIONE DI IMPIANTO DI PUBBLICA ILLUMINAZIONE DELLA PISTA CICLO-PEDONALE IN LOCALITÀ TORRE SALINE ALBINIA | D26: 00017 | E26: COMUNE DI ORBETELLO | F26: In Progress | G26: =SUMIFS(Dettaglio!$I$5:$I$126,Dettaglio!$B$5:$B$126,B26) -> 23093.77 | H26: =IF($G$86=0,"",G26/$G$86) -> 0.013396158 | I26: =SUMIFS(Dettaglio!$J$5:$J$126,Dettaglio!$B$5:$B$126,B26) -> 11316.18 | J26: =IF($I$86=0,"",I26/$I$86) -> 0.0084370308 | K26: =G26-I26 -> 11777.59 | L26: =IF($K$86=0,"",K26/$K$86) -> 0.030778338 | M26: =IF(G26=0,"",K26/G26) -> 0.50998992 | N26: =SUMIFS(Dettaglio!$M$5:$M$126,Dettaglio!$B$5:$B$126,B26) -> 23093.77 | O26: =G26-N26 -> 0 | P26: =COUNTIFS(Dettaglio!$B$5:$B$126,B26,Dettaglio!$D$5:$D$126,"Quadro")+COUNTIFS(Dettaglio!$B$5:$B$126,B26,Dettaglio!$D$5:$D$126,"Variante") -> 0 | Q26: Costi previsti a zero
A27: Standard | B27: S1973 | C27: Manutenzione straordinaria gruppo pompaggio antincendio palazzo comunale | D27: 00017 | E27: COMUNE DI ORBETELLO | F27: Chiusa | G27: =SUMIFS(Dettaglio!$I$5:$I$126,Dettaglio!$B$5:$B$126,B27) -> 9080 | H27: =IF($G$86=0,"",G27/$G$86) -> 0.0052670966 | I27: =SUMIFS(Dettaglio!$J$5:$J$126,Dettaglio!$B$5:$B$126,B27) -> 4538.03 | J27: =IF($I$86=0,"",I27/$I$86) -> 0.0033834296 | K27: =G27-I27 -> 4541.97 | L27: =IF($K$86=0,"",K27/$K$86) -> 0.011869515 | M27: =IF(G27=0,"",K27/G27) -> 0.50021696 | N27: =SUMIFS(Dettaglio!$M$5:$M$126,Dettaglio!$B$5:$B$126,B27) -> 9080 | O27: =G27-N27 -> 0 | P27: =COUNTIFS(Dettaglio!$B$5:$B$126,B27,Dettaglio!$D$5:$D$126,"Quadro")+COUNTIFS(Dettaglio!$B$5:$B$126,B27,Dettaglio!$D$5:$D$126,"Variante") -> 0 | Q27: Costi previsti a zero
A28: Standard | B28: S1980 | C28: INSTALLAZIONE TARGHE SEGNALAZIONE USCITE EMERGENZA CORSI MASCHERATI 2026 | D28: 00446 | E28: ASSOCIAZIONE CARNEVALETTO DA TRE SOLDI | F28: In Progress | G28: =SUMIFS(Dettaglio!$I$5:$I$126,Dettaglio!$B$5:$B$126,B28) -> 1396.2 | H28: =IF($G$86=0,"",G28/$G$86) -> 0.00080990312 | I28: =SUMIFS(Dettaglio!$J$5:$J$126,Dettaglio!$B$5:$B$126,B28) -> 724.68 | J28: =IF($I$86=0,"",I28/$I$86) -> 0.00054030136 | K28: =G28-I28 -> 671.52 | L28: =IF($K$86=0,"",K28/$K$86) -> 0.001754881 | M28: =IF(G28=0,"",K28/G28) -> 0.48096261 | N28: =SUMIFS(Dettaglio!$M$5:$M$126,Dettaglio!$B$5:$B$126,B28) -> 1396.2 | O28: =G28-N28 -> 0 | P28: =COUNTIFS(Dettaglio!$B$5:$B$126,B28,Dettaglio!$D$5:$D$126,"Quadro")+COUNTIFS(Dettaglio!$B$5:$B$126,B28,Dettaglio!$D$5:$D$126,"Variante") -> 0
A29: Standard | B29: S1982 | C29: Manutenzione pubblica illuminazione 2026/2027 | D29: 00002 | E29: COMUNE DI MONTE ARGENTARIO | F29: In Progress | G29: =SUMIFS(Dettaglio!$I$5:$I$126,Dettaglio!$B$5:$B$126,B29) -> 40872.87 | H29: =IF($G$86=0,"",G29/$G$86) -> 0.0237094 | I29: =SUMIFS(Dettaglio!$J$5:$J$126,Dettaglio!$B$5:$B$126,B29) -> 13894.52 | J29: =IF($I$86=0,"",I29/$I$86) -> 0.01035937 | K29: =G29-I29 -> 26978.35 | L29: =IF($K$86=0,"",K29/$K$86) -> 0.070502434 | M29: =IF(G29=0,"",K29/G29) -> 0.66005519 | N29: =SUMIFS(Dettaglio!$M$5:$M$126,Dettaglio!$B$5:$B$126,B29) -> 40872.87 | O29: =G29-N29 -> 0 | P29: =COUNTIFS(Dettaglio!$B$5:$B$126,B29,Dettaglio!$D$5:$D$126,"Quadro")+COUNTIFS(Dettaglio!$B$5:$B$126,B29,Dettaglio!$D$5:$D$126,"Variante") -> 2 | Q29: Costi previsti a zero
A30: Standard | B30: S1986 | C30: ALIMENTAZIONE PUNTI LUCE VIA DELLO SCOGLIO - PORTO SANTO STEFANO | D30: 00002 | E30: COMUNE DI MONTE ARGENTARIO | F30: Chiusa | G30: =SUMIFS(Dettaglio!$I$5:$I$126,Dettaglio!$B$5:$B$126,B30) -> 11600 | H30: =IF($G$86=0,"",G30/$G$86) -> 0.0067288899 | I30: =SUMIFS(Dettaglio!$J$5:$J$126,Dettaglio!$B$5:$B$126,B30) -> 6595.68 | J30: =IF($I$86=0,"",I30/$I$86) -> 0.0049175565 | K30: =G30-I30 -> 5004.32 | L30: =IF($K$86=0,"",K30/$K$86) -> 0.013077773 | M30: =IF(G30=0,"",K30/G30) -> 0.4314069 | N30: =SUMIFS(Dettaglio!$M$5:$M$126,Dettaglio!$B$5:$B$126,B30) -> 11600 | O30: =G30-N30 -> 0 | P30: =COUNTIFS(Dettaglio!$B$5:$B$126,B30,Dettaglio!$D$5:$D$126,"Quadro")+COUNTIFS(Dettaglio!$B$5:$B$126,B30,Dettaglio!$D$5:$D$126,"Variante") -> 1 | Q30: Costi previsti a zero
A31: Standard | B31: S1997 | C31: REALIZZAZIONE DEL NUOVO IMPIANTO DI ILLUMINAZIONE PUBBLICA PRESSO LA STRADA DEL CAMPONE IN PORTO SANTO STEFANO - CIG: BABB02AAC7 | D31: 00002 | E31: COMUNE DI MONTE ARGENTARIO | F31: In Progress | G31: =SUMIFS(Dettaglio!$I$5:$I$126,Dettaglio!$B$5:$B$126,B31) -> 0 | H31: =IF($G$86=0,"",G31/$G$86) -> 0 | I31: =SUMIFS(Dettaglio!$J$5:$J$126,Dettaglio!$B$5:$B$126,B31) -> 28492.69 | J31: =IF($I$86=0,"",I31/$I$86) -> 0.021243361 | K31: =G31-I31 -> -28492.69 | L31: =IF($K$86=0,"",K31/$K$86) -> -0.074459854 | M31: =IF(G31=0,"",K31/G31) | N31: =SUMIFS(Dettaglio!$M$5:$M$126,Dettaglio!$B$5:$B$126,B31) -> 0 | O31: =G31-N31 -> 0 | P31: =COUNTIFS(Dettaglio!$B$5:$B$126,B31,Dettaglio!$D$5:$D$126,"Quadro")+COUNTIFS(Dettaglio!$B$5:$B$126,B31,Dettaglio!$D$5:$D$126,"Variante") -> 0 | Q31: Costi previsti a zero
A32: Standard | B32: S2000 | C32: Lavori di installazione di nuovi punti luce in ampliamento degli impianti di pubblico esistente in Orbetello | D32: 00294 | E32: EDISON NEXT GOVERNMENT S.R.L. | F32: In Progress | G32: =SUMIFS(Dettaglio!$I$5:$I$126,Dettaglio!$B$5:$B$126,B32) -> 36126.04 | H32: =IF($G$86=0,"",G32/$G$86) -> 0.020955875 | I32: =SUMIFS(Dettaglio!$J$5:$J$126,Dettaglio!$B$5:$B$126,B32) -> 12280.67 | J32: =IF($I$86=0,"",I32/$I$86) -> 0.0091561278 | K32: =G32-I32 -> 23845.37 | L32: =IF($K$86=0,"",K32/$K$86) -> 0.062315028 | M32: =IF(G32=0,"",K32/G32) -> 0.66006044 | N32: =SUMIFS(Dettaglio!$M$5:$M$126,Dettaglio!$B$5:$B$126,B32) -> 36126.04 | O32: =G32-N32 -> 0 | P32: =COUNTIFS(Dettaglio!$B$5:$B$126,B32,Dettaglio!$D$5:$D$126,"Quadro")+COUNTIFS(Dettaglio!$B$5:$B$126,B32,Dettaglio!$D$5:$D$126,"Variante") -> 0 | Q32: Costi previsti a zero
A33: Standard | B33: S2007 | C33: ALIMENTAZIONE ELETTRICA COLONNINE EROGAZIONE ACQUA PIAZZALE DEI RIONI E VIA DEL MOLO | D33: 00002 | E33: COMUNE DI MONTE ARGENTARIO | F33: Chiusa | G33: =SUMIFS(Dettaglio!$I$5:$I$126,Dettaglio!$B$5:$B$126,B33) -> 3898.76 | H33: =IF($G$86=0,"",G33/$G$86) -> 0.0022615799 | I33: =SUMIFS(Dettaglio!$J$5:$J$126,Dettaglio!$B$5:$B$126,B33) -> 1060.28 | J33: =IF($I$86=0,"",I33/$I$86) -> 0.00079051544 | K33: =G33-I33 -> 2838.48 | L33: =IF($K$86=0,"",K33/$K$86) -> 0.0074177905 | M33: =IF(G33=0,"",K33/G33) -> 0.72804687 | N33: =SUMIFS(Dettaglio!$M$5:$M$126,Dettaglio!$B$5:$B$126,B33) -> 3898.76 | O33: =G33-N33 -> 0 | P33: =COUNTIFS(Dettaglio!$B$5:$B$126,B33,Dettaglio!$D$5:$D$126,"Quadro")+COUNTIFS(Dettaglio!$B$5:$B$126,B33,Dettaglio!$D$5:$D$126,"Variante") -> 0
A34: Standard | B34: S2028 | C34: LINEA ELETTRICA ILLUMINAZIONE ZONA LASTRICATO-SPALMATOIO | D34: 00500 | E34: CONSORZIO ISOLA DI GIANNUTRI | F34: In Progress | G34: =SUMIFS(Dettaglio!$I$5:$I$126,Dettaglio!$B$5:$B$126,B34) -> 4318.25 | H34: =IF($G$86=0,"",G34/$G$86) -> 0.0025049163 | I34: =SUMIFS(Dettaglio!$J$5:$J$126,Dettaglio!$B$5:$B$126,B34) -> 1613.63 | J34: =IF($I$86=0,"",I34/$I$86) -> 0.0012030779 | K34: =G34-I34 -> 2704.62 | L34: =IF($K$86=0,"",K34/$K$86) -> 0.0070679746 | M34: =IF(G34=0,"",K34/G34) -> 0.62632316 | N34: =SUMIFS(Dettaglio!$M$5:$M$126,Dettaglio!$B$5:$B$126,B34) -> 4318.25 | O34: =G34-N34 -> 0 | P34: =COUNTIFS(Dettaglio!$B$5:$B$126,B34,Dettaglio!$D$5:$D$126,"Quadro")+COUNTIFS(Dettaglio!$B$5:$B$126,B34,Dettaglio!$D$5:$D$126,"Variante") -> 0
A35: Standard | B35: S2035 | C35: Assistenza elettrica per campagna pomodoro 2026 | D35: 00119 | E35: CONSERVE ITALIA SOC. COOP. AGRICOLA | F35: In Progress | G35: =SUMIFS(Dettaglio!$I$5:$I$126,Dettaglio!$B$5:$B$126,B35) -> 10084 | H35: =IF($G$86=0,"",G35/$G$86) -> 0.0058494936 | I35: =SUMIFS(Dettaglio!$J$5:$J$126,Dettaglio!$B$5:$B$126,B35) -> 5462.5 | J35: =IF($I$86=0,"",I35/$I$86) -> 0.0040726889 | K35: =G35-I35 -> 4621.5 | L35: =IF($K$86=0,"",K35/$K$86) -> 0.012077351 | M35: =IF(G35=0,"",K35/G35) -> 0.45830028 | N35: =SUMIFS(Dettaglio!$M$5:$M$126,Dettaglio!$B$5:$B$126,B35) -> 10084 | O35: =G35-N35 -> 0 | P35: =COUNTIFS(Dettaglio!$B$5:$B$126,B35,Dettaglio!$D$5:$D$126,"Quadro")+COUNTIFS(Dettaglio!$B$5:$B$126,B35,Dettaglio!$D$5:$D$126,"Variante") -> 0 | Q35: Costi previsti a zero
A36: Standard | B36: S2048 | C36: IMP. ELETTRICO E MECCANICO NUOVI VINIFICATORI CANTINA SCANSANO (I5514) | D36: 00031 | E36: ICEM SRL | F36: In Progress | G36: =SUMIFS(Dettaglio!$I$5:$I$126,Dettaglio!$B$5:$B$126,B36) -> 0 | H36: =IF($G$86=0,"",G36/$G$86) -> 0 | I36: =SUMIFS(Dettaglio!$J$5:$J$126,Dettaglio!$B$5:$B$126,B36) -> 2566.29 | J36: =IF($I$86=0,"",I36/$I$86) -> 0.0019133548 | K36: =G36-I36 -> -2566.29 | L36: =IF($K$86=0,"",K36/$K$86) -> -0.0067064773 | M36: =IF(G36=0,"",K36/G36) | N36: =SUMIFS(Dettaglio!$M$5:$M$126,Dettaglio!$B$5:$B$126,B36) -> 0 | O36: =G36-N36 -> 0 | P36: =COUNTIFS(Dettaglio!$B$5:$B$126,B36,Dettaglio!$D$5:$D$126,"Quadro")+COUNTIFS(Dettaglio!$B$5:$B$126,B36,Dettaglio!$D$5:$D$126,"Variante") -> 0 | Q36: Costi previsti a zero
A37: Economie | B37: SF0001 | C37: FORNITURA MATERIALI CONSERVE ITALIA | D37: 00119 | E37: CONSERVE ITALIA SOC. COOP. AGRICOLA | F37: In Progress | G37: =SUMIFS(Dettaglio!$I$5:$I$126,Dettaglio!$B$5:$B$126,B37) -> 19191.9 | H37: =IF($G$86=0,"",G37/$G$86) -> 0.011132774 | I37: =SUMIFS(Dettaglio!$J$5:$J$126,Dettaglio!$B$5:$B$126,B37) -> 0 | J37: =IF($I$86=0,"",I37/$I$86) -> 0 | K37: =G37-I37 -> 19191.9 | L37: =IF($K$86=0,"",K37/$K$86) -> 0.05015413 | M37: =IF(G37=0,"",K37/G37) -> 1 | N37: =SUMIFS(Dettaglio!$M$5:$M$126,Dettaglio!$B$5:$B$126,B37) -> 19023.04 | O37: =G37-N37 -> 168.86 | P37: =COUNTIFS(Dettaglio!$B$5:$B$126,B37,Dettaglio!$D$5:$D$126,"Quadro")+COUNTIFS(Dettaglio!$B$5:$B$126,B37,Dettaglio!$D$5:$D$126,"Variante") -> 0
A38: Economie | B38: SF0003 | C38: FORNITURA MATERIALI ICEM | D38: 00031 | E38: ICEM SRL | F38: In Progress | G38: =SUMIFS(Dettaglio!$I$5:$I$126,Dettaglio!$B$5:$B$126,B38) -> 17214.5 | H38: =IF($G$86=0,"",G38/$G$86) -> 0.0099857307 | I38: =SUMIFS(Dettaglio!$J$5:$J$126,Dettaglio!$B$5:$B$126,B38) -> 0 | J38: =IF($I$86=0,"",I38/$I$86) -> 0 | K38: =G38-I38 -> 17214.5 | L38: =IF($K$86=0,"",K38/$K$86) -> 0.044986597 | M38: =IF(G38=0,"",K38/G38) -> 1 | N38: =SUMIFS(Dettaglio!$M$5:$M$126,Dettaglio!$B$5:$B$126,B38) -> 17282.8 | O38: =G38-N38 -> -68.3 | P38: =COUNTIFS(Dettaglio!$B$5:$B$126,B38,Dettaglio!$D$5:$D$126,"Quadro")+COUNTIFS(Dettaglio!$B$5:$B$126,B38,Dettaglio!$D$5:$D$126,"Variante") -> 0
A39: Economie | B39: SF0004 | C39: FORNITURA MATERIALI COIMAR | D39: 00100 | E39: CO.I.MAR. s.r.l. | F39: In Progress | G39: =SUMIFS(Dettaglio!$I$5:$I$126,Dettaglio!$B$5:$B$126,B39) -> 1043.27 | H39: =IF($G$86=0,"",G39/$G$86) -> 0.00060517664 | I39: =SUMIFS(Dettaglio!$J$5:$J$126,Dettaglio!$B$5:$B$126,B39) -> 0 | J39: =IF($I$86=0,"",I39/$I$86) -> 0 | K39: =G39-I39 -> 1043.27 | L39: =IF($K$86=0,"",K39/$K$86) -> 0.0027263741 | M39: =IF(G39=0,"",K39/G39) -> 1 | N39: =SUMIFS(Dettaglio!$M$5:$M$126,Dettaglio!$B$5:$B$126,B39) -> 1043.22 | O39: =G39-N39 -> 0.05 | P39: =COUNTIFS(Dettaglio!$B$5:$B$126,B39,Dettaglio!$D$5:$D$126,"Quadro")+COUNTIFS(Dettaglio!$B$5:$B$126,B39,Dettaglio!$D$5:$D$126,"Variante") -> 0
A40: Economie | B40: SF0011 | C40: FORNITURA MATERIALI VARI | D40: 00143 | E40: NOVELLIS EUGENIO | F40: In Progress | G40: =SUMIFS(Dettaglio!$I$5:$I$126,Dettaglio!$B$5:$B$126,B40) -> 65.67 | H40: =IF($G$86=0,"",G40/$G$86) -> 3.8093638e-05 | I40: =SUMIFS(Dettaglio!$J$5:$J$126,Dettaglio!$B$5:$B$126,B40) -> 0 | J40: =IF($I$86=0,"",I40/$I$86) -> 0 | K40: =G40-I40 -> 65.67 | L40: =IF($K$86=0,"",K40/$K$86) -> 0.0001716152 | M40: =IF(G40=0,"",K40/G40) -> 1 | N40: =SUMIFS(Dettaglio!$M$5:$M$126,Dettaglio!$B$5:$B$126,B40) -> 65.67 | O40: =G40-N40 -> 0 | P40: =COUNTIFS(Dettaglio!$B$5:$B$126,B40,Dettaglio!$D$5:$D$126,"Quadro")+COUNTIFS(Dettaglio!$B$5:$B$126,B40,Dettaglio!$D$5:$D$126,"Variante") -> 0
A41: Economie | B41: SF0015 | C41: FORNITURA MATERIALI CANTINA | D41: 00074 | E41: CANTINA COOP. VIGNAIOLI MORELLINO SCANSANO S.c.a. | F41: In Progress | G41: =SUMIFS(Dettaglio!$I$5:$I$126,Dettaglio!$B$5:$B$126,B41) -> 1724.53 | H41: =IF($G$86=0,"",G41/$G$86) -> 0.0010003597 | I41: =SUMIFS(Dettaglio!$J$5:$J$126,Dettaglio!$B$5:$B$126,B41) -> 0 | J41: =IF($I$86=0,"",I41/$I$86) -> 0 | K41: =G41-I41 -> 1724.53 | L41: =IF($K$86=0,"",K41/$K$86) -> 0.0045067086 | M41: =IF(G41=0,"",K41/G41) -> 1 | N41: =SUMIFS(Dettaglio!$M$5:$M$126,Dettaglio!$B$5:$B$126,B41) -> 1724.53 | O41: =G41-N41 -> 0 | P41: =COUNTIFS(Dettaglio!$B$5:$B$126,B41,Dettaglio!$D$5:$D$126,"Quadro")+COUNTIFS(Dettaglio!$B$5:$B$126,B41,Dettaglio!$D$5:$D$126,"Variante") -> 0
...

Sheet Per cliente
A1: Riepilogo per cliente
A2: Calcolato sulle righe del Dettaglio (ogni variante conta per il proprio cliente).
A4: Cod. cliente | B4: Cliente | C4: N. commesse | D4: Ricavi (€) | E4: % Inc. ricavi | F4: Costi diretti (€) | G4: MLC (€) | H4: % MLC | I4: Fatturato (€) | J4: Scostamento (€)
A5: 00050 | B5: ACQUEDOTTO DEL FIORA S.P.A. | C5: =COUNTIF(Commesse!$D$5:$D$85,A5) -> 2 | D5: =SUMIFS(Dettaglio!$I$5:$I$126,Dettaglio!$F$5:$F$126,A5) -> 589717.49 | E5: =IF($D$49=0,"",D5/$D$49) -> 0.34208139 | F5: =SUMIFS(Dettaglio!$J$5:$J$126,Dettaglio!$F$5:$F$126,A5) -> 573089.1 | G5: =D5-F5 -> 16628.39 | H5: =IF(D5=0,"",G5/D5) -> 0.028197214 | I5: =SUMIFS(Dettaglio!$M$5:$M$126,Dettaglio!$F$5:$F$126,A5) -> 589717.49 | J5: =D5-I5 -> 0
A6: 00311 | B6: ACEA INFRASTRUCTURE S.p.A. - GRUPPO ACEA | C6: =COUNTIF(Commesse!$D$5:$D$85,A6) -> 3 | D6: =SUMIFS(Dettaglio!$I$5:$I$126,Dettaglio!$F$5:$F$126,A6) -> 356117.55 | E6: =IF($D$49=0,"",D6/$D$49) -> 0.2065755 | F6: =SUMIFS(Dettaglio!$J$5:$J$126,Dettaglio!$F$5:$F$126,A6) -> 391308.52 | G6: =D6-F6 -> -35190.97 | H6: =IF(D6=0,"",G6/D6) -> -0.09881841 | I6: =SUMIFS(Dettaglio!$M$5:$M$126,Dettaglio!$F$5:$F$126,A6) -> 356117.55 | J6: =D6-I6 -> 0
A7: 00294 | B7: EDISON NEXT GOVERNMENT S.R.L. | C7: =COUNTIF(Commesse!$D$5:$D$85,A7) -> 3 | D7: =SUMIFS(Dettaglio!$I$5:$I$126,Dettaglio!$F$5:$F$126,A7) -> 171522.98 | E7: =IF($D$49=0,"",D7/$D$49) -> 0.099496488 | F7: =SUMIFS(Dettaglio!$J$5:$J$126,Dettaglio!$F$5:$F$126,A7) -> 72175.88 | G7: =D7-F7 -> 99347.1 | H7: =IF(D7=0,"",G7/D7) -> 0.57920577 | I7: =SUMIFS(Dettaglio!$M$5:$M$126,Dettaglio!$F$5:$F$126,A7) -> 171522.98 | J7: =D7-I7 -> 0
A8: 00248 | B8: REGIONE TOSCANA - GIUNTA REGIONALE | C8: =COUNTIF(Commesse!$D$5:$D$85,A8) -> 2 | D8: =SUMIFS(Dettaglio!$I$5:$I$126,Dettaglio!$F$5:$F$126,A8) -> 154520 | E8: =IF($D$49=0,"",D8/$D$49) -> 0.089633455 | F8: =SUMIFS(Dettaglio!$J$5:$J$126,Dettaglio!$F$5:$F$126,A8) -> 84502.14 | G8: =D8-F8 -> 70017.86 | H8: =IF(D8=0,"",G8/D8) -> 0.45313137 | I8: =SUMIFS(Dettaglio!$M$5:$M$126,Dettaglio!$F$5:$F$126,A8) -> 154520 | J8: =D8-I8 -> 0
A9: 00002 | B9: COMUNE DI MONTE ARGENTARIO | C9: =COUNTIF(Commesse!$D$5:$D$85,A9) -> 9 | D9: =SUMIFS(Dettaglio!$I$5:$I$126,Dettaglio!$F$5:$F$126,A9) -> 147471.51 | E9: =IF($D$49=0,"",D9/$D$49) -> 0.08554479 | F9: =SUMIFS(Dettaglio!$J$5:$J$126,Dettaglio!$F$5:$F$126,A9) -> 102540.43 | G9: =D9-F9 -> 44931.08 | H9: =IF(D9=0,"",G9/D9) -> 0.30467634 | I9: =SUMIFS(Dettaglio!$M$5:$M$126,Dettaglio!$F$5:$F$126,A9) -> 149710.17 | J9: =D9-I9 -> -2238.66
A10: 00017 | B10: COMUNE DI ORBETELLO | C10: =COUNTIF(Commesse!$D$5:$D$85,A10) -> 6 | D10: =SUMIFS(Dettaglio!$I$5:$I$126,Dettaglio!$F$5:$F$126,A10) -> 90602.98 | E10: =IF($D$49=0,"",D10/$D$49) -> 0.052556679 | F10: =SUMIFS(Dettaglio!$J$5:$J$126,Dettaglio!$F$5:$F$126,A10) -> 44361.88 | G10: =D10-F10 -> 46241.1 | H10: =IF(D10=0,"",G10/D10) -> 0.51037063 | I10: =SUMIFS(Dettaglio!$M$5:$M$126,Dettaglio!$F$5:$F$126,A10) -> 90335.95 | J10: =D10-I10 -> 267.03
A11: 00348 | B11: COMUNE DI MONTALTO DI CASTRO | C11: =COUNTIF(Commesse!$D$5:$D$85,A11) -> 1 | D11: =SUMIFS(Dettaglio!$I$5:$I$126,Dettaglio!$F$5:$F$126,A11) -> 57217 | E11: =IF($D$49=0,"",D11/$D$49) -> 0.03319025 | F11: =SUMIFS(Dettaglio!$J$5:$J$126,Dettaglio!$F$5:$F$126,A11) -> 20578.35 | G11: =D11-F11 -> 36638.65 | H11: =IF(D11=0,"",G11/D11) -> 0.64034553 | I11: =SUMIFS(Dettaglio!$M$5:$M$126,Dettaglio!$F$5:$F$126,A11) -> 57217 | J11: =D11-I11 -> 0
A12: 00119 | B12: CONSERVE ITALIA SOC. COOP. AGRICOLA | C12: =COUNTIF(Commesse!$D$5:$D$85,A12) -> 5 | D12: =SUMIFS(Dettaglio!$I$5:$I$126,Dettaglio!$F$5:$F$126,A12) -> 52342.38 | E12: =IF($D$49=0,"",D12/$D$49) -> 0.030362596 | F12: =SUMIFS(Dettaglio!$J$5:$J$126,Dettaglio!$F$5:$F$126,A12) -> 16720 | G12: =D12-F12 -> 35622.38 | H12: =IF(D12=0,"",G12/D12) -> 0.68056477 | I12: =SUMIFS(Dettaglio!$M$5:$M$126,Dettaglio!$F$5:$F$126,A12) -> 52173.53 | J12: =D12-I12 -> 168.85
A13: 00213 | B13: LA SELVA società bioagricola a r.l. | C13: =COUNTIF(Commesse!$D$5:$D$85,A13) -> 2 | D13: =SUMIFS(Dettaglio!$I$5:$I$126,Dettaglio!$F$5:$F$126,A13) -> 20313.95 | E13: =IF($D$49=0,"",D13/$D$49) -> 0.011783649 | F13: =SUMIFS(Dettaglio!$J$5:$J$126,Dettaglio!$F$5:$F$126,A13) -> 10655 | G13: =D13-F13 -> 9658.95 | H13: =IF(D13=0,"",G13/D13) -> 0.4754836 | I13: =SUMIFS(Dettaglio!$M$5:$M$126,Dettaglio!$F$5:$F$126,A13) -> 20083.15 | J13: =D13-I13 -> 230.8
A14: 00031 | B14: ICEM SRL | C14: =COUNTIF(Commesse!$D$5:$D$85,A14) -> 2 | D14: =SUMIFS(Dettaglio!$I$5:$I$126,Dettaglio!$F$5:$F$126,A14) -> 17214.5 | E14: =IF($D$49=0,"",D14/$D$49) -> 0.0099857307 | F14: =SUMIFS(Dettaglio!$J$5:$J$126,Dettaglio!$F$5:$F$126,A14) -> 2566.29 | G14: =D14-F14 -> 14648.21 | H14: =IF(D14=0,"",G14/D14) -> 0.85092277 | I14: =SUMIFS(Dettaglio!$M$5:$M$126,Dettaglio!$F$5:$F$126,A14) -> 17282.8 | J14: =D14-I14 -> -68.3
A15: 00033 | B15: S.E.A.M. s.p.a. AEROPORTO CIVILE DI GROSSETO | C15: =COUNTIF(Commesse!$D$5:$D$85,A15) -> 2 | D15: =SUMIFS(Dettaglio!$I$5:$I$126,Dettaglio!$F$5:$F$126,A15) -> 13982.14 | E15: =IF($D$49=0,"",D15/$D$49) -> 0.0081107139 | F15: =SUMIFS(Dettaglio!$J$5:$J$126,Dettaglio!$F$5:$F$126,A15) -> 6800.5 | G15: =D15-F15 -> 7181.64 | H15: =IF(D15=0,"",G15/D15) -> 0.51362953 | I15: =SUMIFS(Dettaglio!$M$5:$M$126,Dettaglio!$F$5:$F$126,A15) -> 24041.56 | J15: =D15-I15 -> -10059.42
A16: 00269 | B16: TERRE DELL'ETRURIA Società Cooperativa Agricola tra Produttori | C16: =COUNTIF(Commesse!$D$5:$D$85,A16) -> 4 | D16: =SUMIFS(Dettaglio!$I$5:$I$126,Dettaglio!$F$5:$F$126,A16) -> 10516.39 | E16: =IF($D$49=0,"",D16/$D$49) -> 0.006100313 | F16: =SUMIFS(Dettaglio!$J$5:$J$126,Dettaglio!$F$5:$F$126,A16) -> 3888 | G16: =D16-F16 -> 6628.39 | H16: =IF(D16=0,"",G16/D16) -> 0.63029138 | I16: =SUMIFS(Dettaglio!$M$5:$M$126,Dettaglio!$F$5:$F$126,A16) -> 10484.15 | J16: =D16-I16 -> 32.24
... A48: 00293 | B48: CITELUM S.A. | C48: =COUNTIF(Commesse!$D$5:$D$85,A48) -> 0 | D48: =SUMIFS(Dettaglio!$I$5:$I$126,Dettaglio!$F$5:$F$126,A48) -> 0 | E48: =IF($D$49=0,"",D48/$D$49) -> 0 | F48: =SUMIFS(Dettaglio!$J$5:$J$126,Dettaglio!$F$5:$F$126,A48) -> 186.4 | G48: =D48-F48 -> -186.4 | H48: =IF(D48=0,"",G48/D48) | I48: =SUMIFS(Dettaglio!$M$5:$M$126,Dettaglio!$F$5:$F$126,A48) -> 0 | J48: =D48-I48 -> 0
A49: TOTALE | C49: =SUM(C5:C48) -> 81 | D49: =SUM(D5:D48) -> 1723909.9 | E49: =IF(D49=0,"",D49/D49) -> 1 | F49: =SUM(F5:F48) -> 1341251.5 | G49: =SUM(G5:G48) -> 382658.42 | H49: =IF(D49=0,"",G49/D49) -> 0.22197124 | I49: =SUM(I5:I48) -> 1756792.8 | J49: =SUM(J5:J48) -> -32882.9

Sheet Dettaglio
A1: Dettaglio commesse e varianti - CENSINI PAOLO
A2: Ricavi, costi e fatturato (in blu) copiati dal Prospetto Margine Economico (export HTML). MLC = Ricavi - Costi.
A4: Sezione | B4: Commessa madre | C4: Codice | D4: Tipo | E4: Descrizione | F4: Cod. cliente | G4: Cliente | H4: Stato | I4: Ricavi (€) | J4: Costi diretti (€) | K4: MLC (€) | L4: % MLC | M4: Fatturato (€) | N4: Scostamento (€)
A5: Standard | B5: S1185 | C5: S1185 | D5: Base | E5: MONTE ARGENTARIO GESTIONE ILLUMINAZIONE PUBBLICA COMUNALE | F5: 00294 | G5: EDISON NEXT GOVERNMENT S.R.L. | H5: In Progress | I5: 22677.28 | J5: 111.25 | K5: =I5-J5 -> 22566.03 | L5: =IF(I5=0,"",K5/I5) -> 0.99509421 | M5: 22677.28 | N5: =I5-M5 -> 0
A6: Standard | B6: S1185 | C6: S1185ORD | D6: Variante | E6: MONTE ARGENTARIO GESTIONE ILLUMINAZIONE PUBBLICA COMUNALE - MANUTENZIONE ORDINARIA | F6: 00294 | G6: EDISON NEXT GOVERNMENT S.R.L. | H6: In Progress | I6: 0 | J6: 4284.64 | K6: =I6-J6 -> -4284.64 | L6: =IF(I6=0,"",K6/I6) | M6: 0 | N6: =I6-M6 -> 0
A7: Standard | B7: S1185 | C7: S1185STR | D7: Variante | E7: MONTE ARGENTARIO GESTIONE ILLUMINAZIONE PUBBLICA COMUNALE - Manutenzione straordinaria | F7: 00294 | G7: EDISON NEXT GOVERNMENT S.R.L. | H7: In Progress | I7: 33731.17 | J7: 12019.89 | K7: =I7-J7 -> 21711.28 | L7: =IF(I7=0,"",K7/I7) -> 0.6436563 | M7: 33731.17 | N7: =I7-M7 -> 0
A8: Standard | B8: S1186 | C8: S1186 | D8: Base | E8: ORBETELLO GESTIONE ILLUMINAZIONE PUBBLICA COMUNALE | F8: 00294 | G8: EDISON NEXT GOVERNMENT S.R.L. | H8: In Progress | I8: 60357.84 | J8: 329.96 | K8: =I8-J8 -> 60027.88 | L8: =IF(I8=0,"",K8/I8) -> 0.99453327 | M8: 60357.84 | N8: =I8-M8 -> 0
A9: Standard | B9: S1186 | C9: S1186FON | D9: Variante | E9: ILLUMINAZIONE PUBBLICA A SERVIZIO DELLA PIAZZA DELLE REGIONI E DELLA FONTANA | F9: 00293 | G9: CITELUM S.A. | H9: In Progress | I9: 0 | J9: 186.4 | K9: =I9-J9 -> -186.4 | L9: =IF(I9=0,"",K9/I9) | M9: 0 | N9: =I9-M9 -> 0
A10: Standard | B10: S1186 | C10: S1186ORD | D10: Variante | E10: ORBETELLO GESTIONE ILLUMINAZIONE PUBBLICA COMUNALE - MANUTENZIONE ORDINARIA | F10: 00294 | G10: EDISON NEXT GOVERNMENT S.R.L. | H10: In Progress | I10: 0 | J10: 5393.25 | K10: =I10-J10 -> -5393.25 | L10: =IF(I10=0,"",K10/I10) | M10: 0 | N10: =I10-M10 -> 0
A11: Standard | B11: S1186 | C11: S1186Q38 | D11: Quadro | E11: Quadro Matr.: 26051 Tipo: Q.PIGCO.FN.25 | F11: 00294 | G11: EDISON NEXT GOVERNMENT S.R.L. | H11: In Progress | I11: 0 | J11: 274.6 | K11: =I11-J11 -> -274.6 | L11: =IF(I11=0,"",K11/I11) | M11: 0 | N11: =I11-M11 -> 0
A12: Standard | B12: S1186 | C12: S1186STR | D12: Variante | E12: ORBETELLO GESTIONE ILLUMINAZIONE PUBBLICA COMUNALE - MANUTENZIONE STRAORDINARIA | F12: 00294 | G12: EDISON NEXT GOVERNMENT S.R.L. | H12: In Progress | I12: 18630.65 | J12: 37481.62 | K12: =I12-J12 -> -18850.97 | L12: =IF(I12=0,"",K12/I12) -> -1.0118257 | M12: 18630.65 | N12: =I12-M12 -> 0
A13: Standard | B13: S1386 | C13: S1386V08 | D13: Variante | E13: Revamping PLC Santa Marinella Nord | F13: 00311 | G13: ACEA INFRASTRUCTURE S.p.A. - GRUPPO ACEA | H13: In Progress | I13: 0 | J13: 1225.38 | K13: =I13-J13 -> -1225.38 | L13: =IF(I13=0,"",K13/I13) | M13: 0 | N13: =I13-M13 -> 0
A14: Standard | B14: S1419 | C14: S1419 | D14: Base | E14: SOSTITUZIONE DEI PUNTI LUCE A SERVIZIO DELL'IMPIANTO DI ILLUMINAZIONE DEL CAMPO SPORTIVO DI ALBINIA | F14: 00017 | G14: COMUNE DI ORBETELLO | H14: Chiusa | I14: 0 | J14: 1367.26 | K14: =I14-J14 -> -1367.26 | L14: =IF(I14=0,"",K14/I14) | M14: 0 | N14: =I14-M14 -> 0
A15: Standard | B15: S1483 | C15: S1483 | D15: Base | E15: Fornitura in opera di apparati per l'implementazione e manutenzione evolutiva dei sistemi di Telecontrollo 2023 2024 | F15: 00311 | G15: ACEA INFRASTRUCTURE S.p.A. - GRUPPO ACEA | H15: Chiusa | I15: 0 | J15: 4580.86 | K15: =I15-J15 -> -4580.86 | L15: =IF(I15=0,"",K15/I15) | M15: 0 | N15: =I15-M15 -> 0
A16: Standard | B16: S1483 | C16: S1483Q11 | D16: Quadro | E16: Quadro Matr: 25019 Tipo: Q.AD.PC1.FN.10 | F16: 00311 | G16: ACEA INFRASTRUCTURE S.p.A. - GRUPPO ACEA | H16: In Progress | I16: 0 | J16: 29342.6 | K16: =I16-J16 -> -29342.6 | L16: =IF(I16=0,"",K16/I16) | M16: 0 | N16: =I16-M16 -> 0
... A126: Economie | B126: SM0154 | C126: SM0154 | D126: Economia | E126: MANUTENZIONI VARIE CONSORZIO CALA PICCOLA | F126: 00319 | G126: CONSORZIO CALA PICCOLA | H126: In Progress | I126: 2297.69 | J126: 907 | K126: =I126-J126 -> 1390.69 | L126: =IF(I126=0,"",K126/I126) -> 0.60525571 | M126: 2297.68 | N126: =I126-M126 -> 0.01
A127: TOTALE | I127: =SUBTOTAL(9,I5:I126) -> 1723909.9 | J127: =SUBTOTAL(9,J5:J126) -> 1341251.5 | K127: =SUBTOTAL(9,K5:K126) -> 382658.42 | L127: =IF(I127=0,"",K127/I127) -> 0.22197124 | M127: =SUBTOTAL(9,M5:M126) -> 1756792.8 | N127: =SUBTOTAL(9,N5:N126) -> -32882.9
